[Qibo 0.2.12|INFO|2024-10-02 20:45:30]: Loading platform dummy
2024-10-02 20:45:31,488 - qm - INFO     - Starting session: 487100af-c9ea-4fe0-aefe-eac4a720fba0
Traceback (most recent call last):
  File "/nfs/users/elisa.stabilini/calibration/bin/qq", line 8, in <module>
    sys.exit(command())
  File "/nfs/users/elisa.stabilini/calibration/lib/python3.10/site-packages/click/core.py", line 1157, in __call__
    return self.main(*args, **kwargs)
  File "/nfs/users/elisa.stabilini/calibration/lib/python3.10/site-packages/click/core.py", line 1078, in main
    rv = self.invoke(ctx)
  File "/nfs/users/elisa.stabilini/calibration/lib/python3.10/site-packages/click/core.py", line 1688, in invoke
    return _process_result(sub_ctx.command.invoke(sub_ctx))
  File "/nfs/users/elisa.stabilini/calibration/lib/python3.10/site-packages/click/core.py", line 1434, in invoke
    return ctx.invoke(self.callback, **ctx.params)
  File "/nfs/users/elisa.stabilini/calibration/lib/python3.10/site-packages/click/core.py", line 783, in invoke
    return __callback(*args, **kwargs)
  File "/nfs/users/elisa.stabilini/qibocal/src/qibocal/cli/_base.py", line 75, in auto
    autocalibrate(runcard, folder, force, update)
  File "/nfs/users/elisa.stabilini/qibocal/src/qibocal/cli/autocalibration.py", line 26, in autocalibrate
    path = Output.mkdir(folder, force)
  File "/nfs/users/elisa.stabilini/qibocal/src/qibocal/auto/output.py", line 182, in mkdir
    raise RuntimeError(f"Directory {path} already exists.")
RuntimeError: Directory /home/users/elisa.stabilini/cal_qw11q/manual_cal/D2_mask/classification already exists.
